08/08/2020 00:00:09 - [     main.py: 86 -     <module>() ]- INFO - Телеграм бот запущен
08/08/2020 00:00:34 - [     main.py: 86 -     <module>() ]- INFO - Телеграм бот запущен
08/08/2020 00:01:41 - [     main.py: 84 -     <module>() ]- INFO - Телеграм бот запущен
08/08/2020 00:01:55 - [     main.py: 74 -     <module>() ]- INFO - Телеграм бот запущен
08/08/2020 00:02:36 - [     main.py: 75 -     <module>() ]- INFO - Телеграм бот запущен
08/08/2020 00:03:01 - [     main.py: 57 -     <module>() ]- INFO - Телеграм бот запущен
08/08/2020 00:04:10 - [     main.py: 80 -     <module>() ]- INFO - Телеграм бот запущен
08/08/2020 00:05:00 - [     main.py: 80 -     <module>() ]- INFO - Телеграм бот запущен
08/08/2020 00:08:10 - [     main.py:108 -     <module>() ]- INFO - Телеграм бот запущен
08/08/2020 00:08:16 - [     util.py: 68 -          run() ]- ERROR - NameError occurred, args=("name 'types' is not defined",)
Traceback (most recent call last):
  File "/home/zhenisd/Yandex.Disk/pythonProjectSelenium/venv/lib/python3.8/site-packages/telebot/util.py", line 62, in run
    task(*args, **kwargs)
  File "/home/zhenisd/Yandex.Disk/pythonProjectSelenium/main.py", line 79, in start
    keyboard = types.ReplyKeyboardMarkup(resize_keyboard=True)
NameError: name 'types' is not defined

08/08/2020 00:09:21 - [     main.py:107 -     <module>() ]- INFO - Телеграм бот запущен
08/08/2020 00:11:53 - [     main.py: 84 -     <module>() ]- INFO - Телеграм бот запущен
08/08/2020 00:13:06 - [     main.py: 87 -     <module>() ]- INFO - Телеграм бот запущен
08/08/2020 00:13:41 - [     main.py: 87 -     <module>() ]- INFO - Телеграм бот запущен
08/08/2020 00:14:10 - [     main.py: 87 -     <module>() ]- INFO - Телеграм бот запущен
08/08/2020 00:14:41 - [     main.py: 90 -     <module>() ]- INFO - Телеграм бот запущен
08/08/2020 00:14:52 - [     main.py: 90 -     <module>() ]- INFO - Телеграм бот запущен
08/08/2020 00:15:17 - [     main.py: 90 -     <module>() ]- INFO - Телеграм бот запущен
08/08/2020 11:46:22 - [     main.py: 90 -     <module>() ]- INFO - Телеграм бот запущен
08/08/2020 11:48:25 - [     main.py: 89 -     <module>() ]- INFO - Телеграм бот запущен
08/08/2020 11:48:27 - [     util.py: 68 -          run() ]- ERROR - AttributeError occurred, args=("'list' object has no attribute 'to_dict'",)
Traceback (most recent call last):
  File "/home/zhenisd/Yandex.Disk/pythonProjectSelenium/venv/lib/python3.8/site-packages/telebot/util.py", line 62, in run
    task(*args, **kwargs)
  File "/home/zhenisd/Yandex.Disk/pythonProjectSelenium/main.py", line 74, in menu_command
    markup.row(config['MENU_1'])
  File "/home/zhenisd/Yandex.Disk/pythonProjectSelenium/venv/lib/python3.8/site-packages/telebot/types.py", line 850, in row
    btn_array.append(button.to_dict())
AttributeError: 'list' object has no attribute 'to_dict'

08/08/2020 11:48:37 - [     main.py: 89 -     <module>() ]- INFO - Телеграм бот запущен
08/08/2020 11:48:40 - [     util.py: 68 -          run() ]- ERROR - AttributeError occurred, args=("'list' object has no attribute 'to_dict'",)
Traceback (most recent call last):
  File "/home/zhenisd/Yandex.Disk/pythonProjectSelenium/venv/lib/python3.8/site-packages/telebot/util.py", line 62, in run
    task(*args, **kwargs)
  File "/home/zhenisd/Yandex.Disk/pythonProjectSelenium/main.py", line 74, in menu_command
    markup.row(config['MENU_1'][:])
  File "/home/zhenisd/Yandex.Disk/pythonProjectSelenium/venv/lib/python3.8/site-packages/telebot/types.py", line 850, in row
    btn_array.append(button.to_dict())
AttributeError: 'list' object has no attribute 'to_dict'

08/08/2020 11:49:40 - [     main.py: 90 -     <module>() ]- INFO - Телеграм бот запущен
08/08/2020 11:49:43 - [     util.py: 68 -          run() ]- ERROR - AttributeError occurred, args=("'dict' object has no attribute 'to_dict'",)
Traceback (most recent call last):
  File "/home/zhenisd/Yandex.Disk/pythonProjectSelenium/venv/lib/python3.8/site-packages/telebot/util.py", line 62, in run
    task(*args, **kwargs)
  File "/home/zhenisd/Yandex.Disk/pythonProjectSelenium/main.py", line 75, in menu_command
    markup.add(i)
  File "/home/zhenisd/Yandex.Disk/pythonProjectSelenium/venv/lib/python3.8/site-packages/telebot/types.py", line 829, in add
    row.append(button.to_dict())
AttributeError: 'dict' object has no attribute 'to_dict'

08/08/2020 11:50:37 - [     main.py: 90 -     <module>() ]- INFO - Телеграм бот запущен
08/08/2020 11:50:37 - [     util.py: 68 -          run() ]- ERROR - AttributeError occurred, args=("'dict' object has no attribute 'to_dict'",)
Traceback (most recent call last):
  File "/home/zhenisd/Yandex.Disk/pythonProjectSelenium/venv/lib/python3.8/site-packages/telebot/util.py", line 62, in run
    task(*args, **kwargs)
  File "/home/zhenisd/Yandex.Disk/pythonProjectSelenium/main.py", line 75, in menu_command
    markup.add(i)
  File "/home/zhenisd/Yandex.Disk/pythonProjectSelenium/venv/lib/python3.8/site-packages/telebot/types.py", line 829, in add
    row.append(button.to_dict())
AttributeError: 'dict' object has no attribute 'to_dict'

08/08/2020 11:52:01 - [     main.py: 90 -     <module>() ]- INFO - Телеграм бот запущен
08/08/2020 11:52:10 - [     util.py: 68 -          run() ]- ERROR - AttributeError occurred, args=("'dict' object has no attribute 'to_dict'",)
Traceback (most recent call last):
  File "/home/zhenisd/Yandex.Disk/pythonProjectSelenium/venv/lib/python3.8/site-packages/telebot/util.py", line 62, in run
    task(*args, **kwargs)
  File "/home/zhenisd/Yandex.Disk/pythonProjectSelenium/main.py", line 75, in menu_command
    markup.add(i)
  File "/home/zhenisd/Yandex.Disk/pythonProjectSelenium/venv/lib/python3.8/site-packages/telebot/types.py", line 829, in add
    row.append(button.to_dict())
AttributeError: 'dict' object has no attribute 'to_dict'

08/08/2020 11:52:27 - [     main.py: 91 -     <module>() ]- INFO - Телеграм бот запущен
08/08/2020 11:52:29 - [     util.py: 68 -          run() ]- ERROR - AttributeError occurred, args=("'dict' object has no attribute 'to_dict'",)
Traceback (most recent call last):
  File "/home/zhenisd/Yandex.Disk/pythonProjectSelenium/venv/lib/python3.8/site-packages/telebot/util.py", line 62, in run
    task(*args, **kwargs)
  File "/home/zhenisd/Yandex.Disk/pythonProjectSelenium/main.py", line 76, in menu_command
    markup.add(i)
  File "/home/zhenisd/Yandex.Disk/pythonProjectSelenium/venv/lib/python3.8/site-packages/telebot/types.py", line 829, in add
    row.append(button.to_dict())
AttributeError: 'dict' object has no attribute 'to_dict'

08/08/2020 11:53:28 - [     main.py: 91 -     <module>() ]- INFO - Телеграм бот запущен
08/08/2020 11:54:14 - [     main.py: 89 -     <module>() ]- INFO - Телеграм бот запущен
08/08/2020 11:54:16 - [     util.py: 68 -          run() ]- ERROR - AttributeError occurred, args=("'generator' object has no attribute 'to_dict'",)
Traceback (most recent call last):
  File "/home/zhenisd/Yandex.Disk/pythonProjectSelenium/venv/lib/python3.8/site-packages/telebot/util.py", line 62, in run
    task(*args, **kwargs)
  File "/home/zhenisd/Yandex.Disk/pythonProjectSelenium/main.py", line 74, in menu_command
    markup.row(i for i in config['MENU_1'])
  File "/home/zhenisd/Yandex.Disk/pythonProjectSelenium/venv/lib/python3.8/site-packages/telebot/types.py", line 850, in row
    btn_array.append(button.to_dict())
AttributeError: 'generator' object has no attribute 'to_dict'

08/08/2020 11:54:25 - [     main.py: 89 -     <module>() ]- INFO - Телеграм бот запущен
08/08/2020 11:54:27 - [     util.py: 68 -          run() ]- ERROR - AttributeError occurred, args=("'list' object has no attribute 'to_dict'",)
Traceback (most recent call last):
  File "/home/zhenisd/Yandex.Disk/pythonProjectSelenium/venv/lib/python3.8/site-packages/telebot/util.py", line 62, in run
    task(*args, **kwargs)
  File "/home/zhenisd/Yandex.Disk/pythonProjectSelenium/main.py", line 74, in menu_command
    markup.row([i for i in config['MENU_1']])
  File "/home/zhenisd/Yandex.Disk/pythonProjectSelenium/venv/lib/python3.8/site-packages/telebot/types.py", line 850, in row
    btn_array.append(button.to_dict())
AttributeError: 'list' object has no attribute 'to_dict'

08/08/2020 11:55:05 - [     main.py: 89 -     <module>() ]- INFO - Телеграм бот запущен
08/08/2020 11:55:07 - [     util.py: 68 -          run() ]- ERROR - AttributeError occurred, args=("'list' object has no attribute 'to_dict'",)
Traceback (most recent call last):
  File "/home/zhenisd/Yandex.Disk/pythonProjectSelenium/venv/lib/python3.8/site-packages/telebot/util.py", line 62, in run
    task(*args, **kwargs)
  File "/home/zhenisd/Yandex.Disk/pythonProjectSelenium/main.py", line 74, in menu_command
    markup.row(['a', 'b'])
  File "/home/zhenisd/Yandex.Disk/pythonProjectSelenium/venv/lib/python3.8/site-packages/telebot/types.py", line 850, in row
    btn_array.append(button.to_dict())
AttributeError: 'list' object has no attribute 'to_dict'

08/08/2020 11:55:12 - [     main.py: 89 -     <module>() ]- INFO - Телеграм бот запущен
08/08/2020 11:55:39 - [     main.py: 89 -     <module>() ]- INFO - Телеграм бот запущен
08/08/2020 11:55:42 - [     util.py: 68 -          run() ]- ERROR - AttributeError occurred, args=("'generator' object has no attribute 'to_dict'",)
Traceback (most recent call last):
  File "/home/zhenisd/Yandex.Disk/pythonProjectSelenium/venv/lib/python3.8/site-packages/telebot/util.py", line 62, in run
    task(*args, **kwargs)
  File "/home/zhenisd/Yandex.Disk/pythonProjectSelenium/main.py", line 74, in menu_command
    markup.row('a' for i in config['MENU_1'])
  File "/home/zhenisd/Yandex.Disk/pythonProjectSelenium/venv/lib/python3.8/site-packages/telebot/types.py", line 850, in row
    btn_array.append(button.to_dict())
AttributeError: 'generator' object has no attribute 'to_dict'

08/08/2020 11:56:18 - [     main.py: 90 -     <module>() ]- INFO - Телеграм бот запущен
08/08/2020 11:56:20 - [     util.py: 68 -          run() ]- ERROR - AttributeError occurred, args=("'function' object has no attribute 'add'",)
Traceback (most recent call last):
  File "/home/zhenisd/Yandex.Disk/pythonProjectSelenium/venv/lib/python3.8/site-packages/telebot/util.py", line 62, in run
    task(*args, **kwargs)
  File "/home/zhenisd/Yandex.Disk/pythonProjectSelenium/main.py", line 75, in menu_command
    markup.row.add(i)
AttributeError: 'function' object has no attribute 'add'

08/08/2020 11:57:46 - [     main.py: 90 -     <module>() ]- INFO - Телеграм бот запущен
08/08/2020 11:58:05 - [     main.py: 90 -     <module>() ]- INFO - Телеграм бот запущен
08/08/2020 11:58:26 - [     main.py: 90 -     <module>() ]- INFO - Телеграм бот запущен
08/08/2020 11:58:42 - [     main.py: 90 -     <module>() ]- INFO - Телеграм бот запущен
08/08/2020 11:59:22 - [     main.py: 90 -     <module>() ]- INFO - Телеграм бот запущен
08/08/2020 11:59:44 - [     main.py: 90 -     <module>() ]- INFO - Телеграм бот запущен
08/08/2020 11:59:47 - [     util.py: 68 -          run() ]- ERROR - AttributeError occurred, args=("'list' object has no attribute 'to_dict'",)
Traceback (most recent call last):
  File "/home/zhenisd/Yandex.Disk/pythonProjectSelenium/venv/lib/python3.8/site-packages/telebot/util.py", line 62, in run
    task(*args, **kwargs)
  File "/home/zhenisd/Yandex.Disk/pythonProjectSelenium/main.py", line 75, in menu_command
    markup.row(config['MENU_1'])
  File "/home/zhenisd/Yandex.Disk/pythonProjectSelenium/venv/lib/python3.8/site-packages/telebot/types.py", line 850, in row
    btn_array.append(button.to_dict())
AttributeError: 'list' object has no attribute 'to_dict'

08/08/2020 12:00:10 - [     main.py: 90 -     <module>() ]- INFO - Телеграм бот запущен
08/08/2020 12:00:15 - [     util.py: 68 -          run() ]- ERROR - AttributeError occurred, args=("'list' object has no attribute 'to_dict'",)
Traceback (most recent call last):
  File "/home/zhenisd/Yandex.Disk/pythonProjectSelenium/venv/lib/python3.8/site-packages/telebot/util.py", line 62, in run
    task(*args, **kwargs)
  File "/home/zhenisd/Yandex.Disk/pythonProjectSelenium/main.py", line 75, in menu_command
    markup.row(config['MENU_1'])
  File "/home/zhenisd/Yandex.Disk/pythonProjectSelenium/venv/lib/python3.8/site-packages/telebot/types.py", line 850, in row
    btn_array.append(button.to_dict())
AttributeError: 'list' object has no attribute 'to_dict'

08/08/2020 12:01:19 - [     main.py: 91 -     <module>() ]- INFO - Телеграм бот запущен
08/08/2020 12:01:21 - [     util.py: 68 -          run() ]- ERROR - AttributeError occurred, args=("'function' object has no attribute 'to_dict'",)
Traceback (most recent call last):
  File "/home/zhenisd/Yandex.Disk/pythonProjectSelenium/venv/lib/python3.8/site-packages/telebot/util.py", line 62, in run
    task(*args, **kwargs)
  File "/home/zhenisd/Yandex.Disk/pythonProjectSelenium/main.py", line 76, in menu_command
    markup.row(lambda x: x, config['MENU_1'])
  File "/home/zhenisd/Yandex.Disk/pythonProjectSelenium/venv/lib/python3.8/site-packages/telebot/types.py", line 850, in row
    btn_array.append(button.to_dict())
AttributeError: 'function' object has no attribute 'to_dict'

08/08/2020 12:01:53 - [     main.py: 92 -     <module>() ]- INFO - Телеграм бот запущен
08/08/2020 12:01:55 - [     util.py: 68 -          run() ]- ERROR - AttributeError occurred, args=("'function' object has no attribute 'to_dict'",)
Traceback (most recent call last):
  File "/home/zhenisd/Yandex.Disk/pythonProjectSelenium/venv/lib/python3.8/site-packages/telebot/util.py", line 62, in run
    task(*args, **kwargs)
  File "/home/zhenisd/Yandex.Disk/pythonProjectSelenium/main.py", line 77, in menu_command
    markup.row(lambda x: x, config['MENU_1'])
  File "/home/zhenisd/Yandex.Disk/pythonProjectSelenium/venv/lib/python3.8/site-packages/telebot/types.py", line 850, in row
    btn_array.append(button.to_dict())
AttributeError: 'function' object has no attribute 'to_dict'

08/08/2020 12:02:10 - [     main.py: 92 -     <module>() ]- INFO - Телеграм бот запущен
08/08/2020 12:02:12 - [     util.py: 68 -          run() ]- ERROR - TypeError occurred, args=('type() takes 1 or 3 arguments',)
Traceback (most recent call last):
  File "/home/zhenisd/Yandex.Disk/pythonProjectSelenium/venv/lib/python3.8/site-packages/telebot/util.py", line 62, in run
    task(*args, **kwargs)
  File "/home/zhenisd/Yandex.Disk/pythonProjectSelenium/main.py", line 76, in menu_command
    print(type(lambda x: x, config['MENU_1']))
TypeError: type() takes 1 or 3 arguments

08/08/2020 12:03:49 - [     main.py:104 -     <module>() ]- INFO - Телеграм бот запущен
08/08/2020 12:03:51 - [     util.py: 68 -          run() ]- ERROR - TypeError occurred, args=('type() takes 1 or 3 arguments',)
Traceback (most recent call last):
  File "/home/zhenisd/Yandex.Disk/pythonProjectSelenium/venv/lib/python3.8/site-packages/telebot/util.py", line 62, in run
    task(*args, **kwargs)
  File "/home/zhenisd/Yandex.Disk/pythonProjectSelenium/main.py", line 88, in menu_command
    print(type(lambda x: x, config['MENU_1']))
TypeError: type() takes 1 or 3 arguments

08/08/2020 12:04:12 - [     main.py:104 -     <module>() ]- INFO - Телеграм бот запущен
08/08/2020 12:04:14 - [     util.py: 68 -          run() ]- ERROR - TypeError occurred, args=('type() takes 1 or 3 arguments',)
Traceback (most recent call last):
  File "/home/zhenisd/Yandex.Disk/pythonProjectSelenium/venv/lib/python3.8/site-packages/telebot/util.py", line 62, in run
    task(*args, **kwargs)
  File "/home/zhenisd/Yandex.Disk/pythonProjectSelenium/main.py", line 88, in menu_command
    print(type(lambda x: x, config['MENU_1']))
TypeError: type() takes 1 or 3 arguments

08/08/2020 12:04:34 - [     main.py:101 -     <module>() ]- INFO - Телеграм бот запущен
08/08/2020 12:05:34 - [     main.py: 89 -     <module>() ]- INFO - Телеграм бот запущен
08/08/2020 12:05:36 - [     util.py: 68 -          run() ]- ERROR - TypeError occurred, args=("'ReplyKeyboardMarkup' object is not callable",)
Traceback (most recent call last):
  File "/home/zhenisd/Yandex.Disk/pythonProjectSelenium/venv/lib/python3.8/site-packages/telebot/util.py", line 62, in run
    task(*args, **kwargs)
  File "/home/zhenisd/Yandex.Disk/pythonProjectSelenium/main.py", line 74, in menu_command
    markup(str(config['MENU_1']))
TypeError: 'ReplyKeyboardMarkup' object is not callable

08/08/2020 12:05:55 - [     main.py: 89 -     <module>() ]- INFO - Телеграм бот запущен
08/08/2020 12:06:08 - [     main.py: 89 -     <module>() ]- INFO - Телеграм бот запущен
08/08/2020 12:06:09 - [     util.py: 68 -          run() ]- ERROR - AttributeError occurred, args=("'list' object has no attribute 'to_dict'",)
Traceback (most recent call last):
  File "/home/zhenisd/Yandex.Disk/pythonProjectSelenium/venv/lib/python3.8/site-packages/telebot/util.py", line 62, in run
    task(*args, **kwargs)
  File "/home/zhenisd/Yandex.Disk/pythonProjectSelenium/main.py", line 74, in menu_command
    markup.add(config['MENU_1'])
  File "/home/zhenisd/Yandex.Disk/pythonProjectSelenium/venv/lib/python3.8/site-packages/telebot/types.py", line 829, in add
    row.append(button.to_dict())
AttributeError: 'list' object has no attribute 'to_dict'

08/08/2020 12:06:30 - [     main.py: 89 -     <module>() ]- INFO - Телеграм бот запущен
08/08/2020 12:06:32 - [     util.py: 68 -          run() ]- ERROR - AttributeError occurred, args=("'generator' object has no attribute 'to_dict'",)
Traceback (most recent call last):
  File "/home/zhenisd/Yandex.Disk/pythonProjectSelenium/venv/lib/python3.8/site-packages/telebot/util.py", line 62, in run
    task(*args, **kwargs)
  File "/home/zhenisd/Yandex.Disk/pythonProjectSelenium/main.py", line 74, in menu_command
    markup.add(item for item in config['MENU_1'])
  File "/home/zhenisd/Yandex.Disk/pythonProjectSelenium/venv/lib/python3.8/site-packages/telebot/types.py", line 829, in add
    row.append(button.to_dict())
AttributeError: 'generator' object has no attribute 'to_dict'

08/08/2020 12:06:43 - [     main.py: 90 -     <module>() ]- INFO - Телеграм бот запущен
08/08/2020 12:06:47 - [     util.py: 68 -          run() ]- ERROR - AttributeError occurred, args=("'generator' object has no attribute 'to_dict'",)
Traceback (most recent call last):
  File "/home/zhenisd/Yandex.Disk/pythonProjectSelenium/venv/lib/python3.8/site-packages/telebot/util.py", line 62, in run
    task(*args, **kwargs)
  File "/home/zhenisd/Yandex.Disk/pythonProjectSelenium/main.py", line 75, in menu_command
    markup.add(item for item in config['MENU_1'])
  File "/home/zhenisd/Yandex.Disk/pythonProjectSelenium/venv/lib/python3.8/site-packages/telebot/types.py", line 829, in add
    row.append(button.to_dict())
AttributeError: 'generator' object has no attribute 'to_dict'

08/08/2020 12:07:00 - [     main.py: 90 -     <module>() ]- INFO - Телеграм бот запущен
08/08/2020 12:07:05 - [     main.py: 90 -     <module>() ]- INFO - Телеграм бот запущен
08/08/2020 12:07:07 - [     util.py: 68 -          run() ]- ERROR - AttributeError occurred, args=("'list' object has no attribute 'keys'",)
Traceback (most recent call last):
  File "/home/zhenisd/Yandex.Disk/pythonProjectSelenium/venv/lib/python3.8/site-packages/telebot/util.py", line 62, in run
    task(*args, **kwargs)
  File "/home/zhenisd/Yandex.Disk/pythonProjectSelenium/main.py", line 74, in menu_command
    print(item for item in config['MENU_1'].keys())
AttributeError: 'list' object has no attribute 'keys'

08/08/2020 12:07:21 - [     main.py: 90 -     <module>() ]- INFO - Телеграм бот запущен
08/08/2020 12:07:23 - [     util.py: 68 -          run() ]- ERROR - AttributeError occurred, args=("'generator' object has no attribute 'to_dict'",)
Traceback (most recent call last):
  File "/home/zhenisd/Yandex.Disk/pythonProjectSelenium/venv/lib/python3.8/site-packages/telebot/util.py", line 62, in run
    task(*args, **kwargs)
  File "/home/zhenisd/Yandex.Disk/pythonProjectSelenium/main.py", line 75, in menu_command
    markup.add(item for item in config['MENU_1'])
  File "/home/zhenisd/Yandex.Disk/pythonProjectSelenium/venv/lib/python3.8/site-packages/telebot/types.py", line 829, in add
    row.append(button.to_dict())
AttributeError: 'generator' object has no attribute 'to_dict'

08/08/2020 12:07:50 - [     main.py: 90 -     <module>() ]- INFO - Телеграм бот запущен
08/08/2020 12:07:52 - [     util.py: 68 -          run() ]- ERROR - AttributeError occurred, args=("'list' object has no attribute 'to_dict'",)
Traceback (most recent call last):
  File "/home/zhenisd/Yandex.Disk/pythonProjectSelenium/venv/lib/python3.8/site-packages/telebot/util.py", line 62, in run
    task(*args, **kwargs)
  File "/home/zhenisd/Yandex.Disk/pythonProjectSelenium/main.py", line 75, in menu_command
    markup.row([item for item in config['MENU_1']])
  File "/home/zhenisd/Yandex.Disk/pythonProjectSelenium/venv/lib/python3.8/site-packages/telebot/types.py", line 850, in row
    btn_array.append(button.to_dict())
AttributeError: 'list' object has no attribute 'to_dict'

08/08/2020 12:08:57 - [     main.py: 90 -     <module>() ]- INFO - Телеграм бот запущен
08/08/2020 12:08:58 - [     util.py: 68 -          run() ]- ERROR - AttributeError occurred, args=("'list' object has no attribute 'to_dict'",)
Traceback (most recent call last):
  File "/home/zhenisd/Yandex.Disk/pythonProjectSelenium/venv/lib/python3.8/site-packages/telebot/util.py", line 62, in run
    task(*args, **kwargs)
  File "/home/zhenisd/Yandex.Disk/pythonProjectSelenium/main.py", line 75, in menu_command
    markup.row(['АРЕНДА', 'ПРОДАЖА', 'ПОКУПКА'])
  File "/home/zhenisd/Yandex.Disk/pythonProjectSelenium/venv/lib/python3.8/site-packages/telebot/types.py", line 850, in row
    btn_array.append(button.to_dict())
AttributeError: 'list' object has no attribute 'to_dict'

08/08/2020 12:09:06 - [     main.py: 90 -     <module>() ]- INFO - Телеграм бот запущен
08/08/2020 12:10:02 - [     main.py: 90 -     <module>() ]- INFO - Телеграм бот запущен
08/08/2020 12:11:28 - [     main.py: 89 -     <module>() ]- INFO - Телеграм бот запущен
08/08/2020 12:12:52 - [     main.py: 93 -     <module>() ]- INFO - Телеграм бот запущен
08/08/2020 12:12:55 - [     util.py: 68 -          run() ]- ERROR - AttributeError occurred, args=("'dict' object has no attribute 'to_dict'",)
Traceback (most recent call last):
  File "/home/zhenisd/Yandex.Disk/pythonProjectSelenium/venv/lib/python3.8/site-packages/telebot/util.py", line 62, in run
    task(*args, **kwargs)
  File "/home/zhenisd/Yandex.Disk/pythonProjectSelenium/main.py", line 78, in menu_command
    markup.row(*config['MENU_2'])
  File "/home/zhenisd/Yandex.Disk/pythonProjectSelenium/venv/lib/python3.8/site-packages/telebot/types.py", line 850, in row
    btn_array.append(button.to_dict())
AttributeError: 'dict' object has no attribute 'to_dict'

08/08/2020 12:13:10 - [     main.py: 95 -     <module>() ]- INFO - Телеграм бот запущен
08/08/2020 12:13:15 - [     util.py: 68 -          run() ]- ERROR - AttributeError occurred, args=("'dict' object has no attribute 'to_dict'",)
Traceback (most recent call last):
  File "/home/zhenisd/Yandex.Disk/pythonProjectSelenium/venv/lib/python3.8/site-packages/telebot/util.py", line 62, in run
    task(*args, **kwargs)
  File "/home/zhenisd/Yandex.Disk/pythonProjectSelenium/main.py", line 80, in menu_command
    markup.row(*config['MENU_2'])
  File "/home/zhenisd/Yandex.Disk/pythonProjectSelenium/venv/lib/python3.8/site-packages/telebot/types.py", line 850, in row
    btn_array.append(button.to_dict())
AttributeError: 'dict' object has no attribute 'to_dict'

08/08/2020 12:13:47 - [     main.py: 95 -     <module>() ]- INFO - Телеграм бот запущен
08/08/2020 12:14:42 - [     main.py: 96 -     <module>() ]- INFO - Телеграм бот запущен
08/08/2020 12:15:13 - [     main.py: 97 -     <module>() ]- INFO - Телеграм бот запущен
08/08/2020 12:16:58 - [     main.py:104 -     <module>() ]- INFO - Телеграм бот запущен
08/08/2020 12:19:05 - [     main.py:104 -     <module>() ]- INFO - Телеграм бот запущен
08/08/2020 12:19:27 - [     main.py:106 -     <module>() ]- INFO - Телеграм бот запущен
08/08/2020 12:22:31 - [     main.py:105 -     <module>() ]- INFO - Телеграм бот запущен
08/08/2020 12:23:26 - [     main.py:105 -     <module>() ]- INFO - Телеграм бот запущен
08/08/2020 12:24:48 - [     main.py:101 -     <module>() ]- INFO - Телеграм бот запущен
08/08/2020 12:43:52 - [     main.py:101 -     <module>() ]- INFO - Телеграм бот запущен
08/08/2020 12:44:23 - [     main.py:101 -     <module>() ]- INFO - Телеграм бот запущен
08/08/2020 12:45:30 - [     main.py:101 -     <module>() ]- INFO - Телеграм бот запущен
08/08/2020 12:45:46 - [     main.py:101 -     <module>() ]- INFO - Телеграм бот запущен
08/08/2020 12:48:20 - [     main.py:107 -     <module>() ]- INFO - Телеграм бот запущен
08/08/2020 12:50:12 - [     main.py:107 -     <module>() ]- INFO - Телеграм бот запущен
08/08/2020 13:03:57 - [     main.py:107 -     <module>() ]- INFO - Телеграм бот запущен
08/08/2020 13:04:11 - [     main.py:107 -     <module>() ]- INFO - Телеграм бот запущен
08/08/2020 13:40:27 - [     main.py: 70 -     <module>() ]- INFO - Телеграм бот запущен
08/08/2020 13:40:30 - [     util.py: 68 -          run() ]- ERROR - NameError occurred, args=("name 'change_user_config' is not defined",)
Traceback (most recent call last):
  File "/home/zhenisd/Yandex.Disk/pythonProjectSelenium/venv/lib/python3.8/site-packages/telebot/util.py", line 62, in run
    task(*args, **kwargs)
  File "/home/zhenisd/Yandex.Disk/pythonProjectSelenium/main.py", line 46, in menu_command
    change_user_config(message.text)
NameError: name 'change_user_config' is not defined

08/08/2020 13:40:57 - [     main.py: 70 -     <module>() ]- INFO - Телеграм бот запущен
08/08/2020 13:40:59 - [     util.py: 68 -          run() ]- ERROR - AttributeError occurred, args=("'dict' object has no attribute 'to_dict'",)
Traceback (most recent call last):
  File "/home/zhenisd/Yandex.Disk/pythonProjectSelenium/venv/lib/python3.8/site-packages/telebot/util.py", line 62, in run
    task(*args, **kwargs)
  File "/home/zhenisd/Yandex.Disk/pythonProjectSelenium/main.py", line 49, in menu_command
    markup.row(*config['MENU_0'][1::])
  File "/home/zhenisd/Yandex.Disk/pythonProjectSelenium/venv/lib/python3.8/site-packages/telebot/types.py", line 850, in row
    btn_array.append(button.to_dict())
AttributeError: 'dict' object has no attribute 'to_dict'

08/08/2020 13:41:19 - [     main.py: 71 -     <module>() ]- INFO - Телеграм бот запущен
08/08/2020 13:41:20 - [     util.py: 68 -          run() ]- ERROR - AttributeError occurred, args=("'dict' object has no attribute 'to_dict'",)
Traceback (most recent call last):
  File "/home/zhenisd/Yandex.Disk/pythonProjectSelenium/venv/lib/python3.8/site-packages/telebot/util.py", line 62, in run
    task(*args, **kwargs)
  File "/home/zhenisd/Yandex.Disk/pythonProjectSelenium/main.py", line 50, in menu_command
    markup.row(*config['MENU_0'][1::])
  File "/home/zhenisd/Yandex.Disk/pythonProjectSelenium/venv/lib/python3.8/site-packages/telebot/types.py", line 850, in row
    btn_array.append(button.to_dict())
AttributeError: 'dict' object has no attribute 'to_dict'

08/08/2020 13:41:32 - [     main.py: 71 -     <module>() ]- INFO - Телеграм бот запущен
08/08/2020 13:41:34 - [     util.py: 68 -          run() ]- ERROR - AttributeError occurred, args=("'list' object has no attribute 'keys'",)
Traceback (most recent call last):
  File "/home/zhenisd/Yandex.Disk/pythonProjectSelenium/venv/lib/python3.8/site-packages/telebot/util.py", line 62, in run
    task(*args, **kwargs)
  File "/home/zhenisd/Yandex.Disk/pythonProjectSelenium/main.py", line 49, in menu_command
    print(*config['MENU_0'][1::].keys())
AttributeError: 'list' object has no attribute 'keys'

08/08/2020 13:41:40 - [     main.py: 71 -     <module>() ]- INFO - Телеграм бот запущен
08/08/2020 13:41:41 - [     util.py: 68 -          run() ]- ERROR - AttributeError occurred, args=("'list' object has no attribute 'keys'",)
Traceback (most recent call last):
  File "/home/zhenisd/Yandex.Disk/pythonProjectSelenium/venv/lib/python3.8/site-packages/telebot/util.py", line 62, in run
    task(*args, **kwargs)
  File "/home/zhenisd/Yandex.Disk/pythonProjectSelenium/main.py", line 49, in menu_command
    print(*config['MENU_0'][1::].keys)
AttributeError: 'list' object has no attribute 'keys'

08/08/2020 13:42:47 - [     main.py: 71 -     <module>() ]- INFO - Телеграм бот запущен
08/08/2020 13:42:48 - [     util.py: 68 -          run() ]- ERROR - AttributeError occurred, args=("'dict' object has no attribute 'to_dict'",)
Traceback (most recent call last):
  File "/home/zhenisd/Yandex.Disk/pythonProjectSelenium/venv/lib/python3.8/site-packages/telebot/util.py", line 62, in run
    task(*args, **kwargs)
  File "/home/zhenisd/Yandex.Disk/pythonProjectSelenium/main.py", line 50, in menu_command
    markup.row(*config['MENU_0'][1::])
  File "/home/zhenisd/Yandex.Disk/pythonProjectSelenium/venv/lib/python3.8/site-packages/telebot/types.py", line 850, in row
    btn_array.append(button.to_dict())
AttributeError: 'dict' object has no attribute 'to_dict'

08/08/2020 13:43:12 - [     main.py: 71 -     <module>() ]- INFO - Телеграм бот запущен
08/08/2020 13:43:14 - [     util.py: 68 -          run() ]- ERROR - AttributeError occurred, args=("'dict' object has no attribute 'to_dict'",)
Traceback (most recent call last):
  File "/home/zhenisd/Yandex.Disk/pythonProjectSelenium/venv/lib/python3.8/site-packages/telebot/util.py", line 62, in run
    task(*args, **kwargs)
  File "/home/zhenisd/Yandex.Disk/pythonProjectSelenium/main.py", line 50, in menu_command
    markup.row(*config['MENU_0'][1::])
  File "/home/zhenisd/Yandex.Disk/pythonProjectSelenium/venv/lib/python3.8/site-packages/telebot/types.py", line 850, in row
    btn_array.append(button.to_dict())
AttributeError: 'dict' object has no attribute 'to_dict'

08/08/2020 13:43:26 - [     main.py: 71 -     <module>() ]- INFO - Телеграм бот запущен
08/08/2020 13:43:28 - [     util.py: 68 -          run() ]- ERROR - AttributeError occurred, args=("'dict' object has no attribute 'to_dict'",)
Traceback (most recent call last):
  File "/home/zhenisd/Yandex.Disk/pythonProjectSelenium/venv/lib/python3.8/site-packages/telebot/util.py", line 62, in run
    task(*args, **kwargs)
  File "/home/zhenisd/Yandex.Disk/pythonProjectSelenium/main.py", line 50, in menu_command
    markup.row(*config['MENU_0'][1::])
  File "/home/zhenisd/Yandex.Disk/pythonProjectSelenium/venv/lib/python3.8/site-packages/telebot/types.py", line 850, in row
    btn_array.append(button.to_dict())
AttributeError: 'dict' object has no attribute 'to_dict'

08/08/2020 14:57:42 - [     main.py: 76 -     <module>() ]- INFO - Телеграм бот запущен
08/08/2020 15:08:12 - [     main.py: 76 -     <module>() ]- INFO - Телеграм бот запущен
08/08/2020 15:08:15 - [     util.py: 68 -          run() ]- ERROR - TypeError occurred, args=('list indices must be integers or slices, not str',)
Traceback (most recent call last):
  File "/home/zhenisd/Yandex.Disk/pythonProjectSelenium/venv/lib/python3.8/site-packages/telebot/util.py", line 62, in run
    task(*args, **kwargs)
  File "/home/zhenisd/Yandex.Disk/pythonProjectSelenium/main.py", line 55, in menu_command
    markup.row(*config['MENU']['MENU_0'][1::])
TypeError: list indices must be integers or slices, not str

08/08/2020 15:09:03 - [     main.py: 77 -     <module>() ]- INFO - Телеграм бот запущен
08/08/2020 15:09:06 - [     util.py: 68 -          run() ]- ERROR - TypeError occurred, args=('list indices must be integers or slices, not str',)
Traceback (most recent call last):
  File "/home/zhenisd/Yandex.Disk/pythonProjectSelenium/venv/lib/python3.8/site-packages/telebot/util.py", line 62, in run
    task(*args, **kwargs)
  File "/home/zhenisd/Yandex.Disk/pythonProjectSelenium/main.py", line 56, in menu_command
    markup.row(*config['MENU']['MENU_0'][1::])
TypeError: list indices must be integers or slices, not str

08/08/2020 15:09:32 - [     main.py: 77 -     <module>() ]- INFO - Телеграм бот запущен
08/08/2020 15:09:34 - [     util.py: 68 -          run() ]- ERROR - TypeError occurred, args=('list indices must be integers or slices, not str',)
Traceback (most recent call last):
  File "/home/zhenisd/Yandex.Disk/pythonProjectSelenium/venv/lib/python3.8/site-packages/telebot/util.py", line 62, in run
    task(*args, **kwargs)
  File "/home/zhenisd/Yandex.Disk/pythonProjectSelenium/main.py", line 54, in menu_command
    print(config['MENU']['MENU_0'])
TypeError: list indices must be integers or slices, not str

08/08/2020 15:10:07 - [     main.py: 77 -     <module>() ]- INFO - Телеграм бот запущен
08/08/2020 15:13:37 - [     main.py: 77 -     <module>() ]- INFO - Телеграм бот запущен
08/08/2020 15:13:40 - [     util.py: 68 -          run() ]- ERROR - TypeError occurred, args=('list indices must be integers or slices, not str',)
Traceback (most recent call last):
  File "/home/zhenisd/Yandex.Disk/pythonProjectSelenium/venv/lib/python3.8/site-packages/telebot/util.py", line 62, in run
    task(*args, **kwargs)
  File "/home/zhenisd/Yandex.Disk/pythonProjectSelenium/main.py", line 56, in menu_command
    markup.row(*config['MENU']['MENU_0'][1::])
TypeError: list indices must be integers or slices, not str

08/08/2020 15:19:01 - [     main.py: 77 -     <module>() ]- INFO - Телеграм бот запущен
08/08/2020 15:19:06 - [     util.py: 68 -          run() ]- ERROR - TypeError occurred, args=('list indices must be integers or slices, not str',)
Traceback (most recent call last):
  File "/home/zhenisd/Yandex.Disk/pythonProjectSelenium/venv/lib/python3.8/site-packages/telebot/util.py", line 62, in run
    task(*args, **kwargs)
  File "/home/zhenisd/Yandex.Disk/pythonProjectSelenium/main.py", line 59, in menu_command
    elif message.text == config['MENU']['MENU_0'][1]:   # RENT
TypeError: list indices must be integers or slices, not str

08/08/2020 15:19:39 - [     main.py: 77 -     <module>() ]- INFO - Телеграм бот запущен
08/08/2020 15:19:41 - [     util.py: 68 -          run() ]- ERROR - TypeError occurred, args=('list indices must be integers or slices, not str',)
Traceback (most recent call last):
  File "/home/zhenisd/Yandex.Disk/pythonProjectSelenium/venv/lib/python3.8/site-packages/telebot/util.py", line 62, in run
    task(*args, **kwargs)
  File "/home/zhenisd/Yandex.Disk/pythonProjectSelenium/main.py", line 56, in menu_command
    markup.row(*config['MENU']['MENU_0'][1::])
TypeError: list indices must be integers or slices, not str

08/08/2020 15:54:08 - [     main.py: 77 -     <module>() ]- INFO - Телеграм бот запущен
08/08/2020 15:54:16 - [     util.py: 68 -          run() ]- ERROR - KeyError occurred, args=('MENU_2',)
Traceback (most recent call last):
  File "/home/zhenisd/Yandex.Disk/pythonProjectSelenium/venv/lib/python3.8/site-packages/telebot/util.py", line 62, in run
    task(*args, **kwargs)
  File "/home/zhenisd/Yandex.Disk/pythonProjectSelenium/main.py", line 60, in menu_command
    markup.row(*config['MENU_'+ str(i)][1:4])  # TODO: добавить другие типы недвижимости
KeyError: 'MENU_2'

08/08/2020 15:57:20 - [     main.py: 77 -     <module>() ]- INFO - Телеграм бот запущен
08/08/2020 15:57:21 - [     util.py: 68 -          run() ]- ERROR - KeyError occurred, args=('MENU_2',)
Traceback (most recent call last):
  File "/home/zhenisd/Yandex.Disk/pythonProjectSelenium/venv/lib/python3.8/site-packages/telebot/util.py", line 62, in run
    task(*args, **kwargs)
  File "/home/zhenisd/Yandex.Disk/pythonProjectSelenium/main.py", line 60, in menu_command
    markup.row(*config['MENU_' + str(i)][1:4])  # TODO: добавить другие типы недвижимости
KeyError: 'MENU_2'

08/08/2020 16:00:16 - [     main.py: 80 -     <module>() ]- INFO - Телеграм бот запущен
08/08/2020 16:00:18 - [     main.py: 67 - menu_command() ]- WARNING - Нет такого меню MENU_9
08/08/2020 16:00:25 - [     main.py: 67 - menu_command() ]- WARNING - Нет такого меню MENU_9
08/08/2020 16:25:13 - [     main.py: 81 -     <module>() ]- INFO - Телеграм бот запущен
08/08/2020 16:25:38 - [     main.py: 68 - menu_command() ]- WARNING - Нет такого меню MENU_9
08/08/2020 16:32:25 - [     main.py: 81 -     <module>() ]- INFO - Телеграм бот запущен
08/08/2020 16:32:42 - [     main.py: 68 - menu_command() ]- WARNING - Нет такого меню MENU_8
08/08/2020 16:33:48 - [     main.py: 81 -     <module>() ]- INFO - Телеграм бот запущен
08/08/2020 16:34:12 - [     main.py: 81 -     <module>() ]- INFO - Телеграм бот запущен
08/08/2020 16:34:25 - [     main.py: 68 - menu_command() ]- WARNING - Нет такого меню MENU_8
08/08/2020 16:35:41 - [     main.py: 81 -     <module>() ]- INFO - Телеграм бот запущен
08/08/2020 16:36:37 - [     main.py: 82 -     <module>() ]- INFO - Телеграм бот запущен
08/08/2020 16:37:13 - [     main.py: 80 -     <module>() ]- INFO - Телеграм бот запущен
08/08/2020 16:37:40 - [     main.py: 80 -     <module>() ]- INFO - Телеграм бот запущен
08/08/2020 16:37:56 - [     main.py: 67 - menu_command() ]- WARNING - Нет такого меню MENU_8
08/08/2020 16:37:58 - [     main.py: 67 - menu_command() ]- WARNING - Нет такого меню MENU_9
08/08/2020 16:38:00 - [     main.py: 67 - menu_command() ]- WARNING - Нет такого меню MENU_10
08/08/2020 16:39:34 - [     main.py: 83 -     <module>() ]- INFO - Телеграм бот запущен
08/08/2020 16:39:48 - [     main.py: 67 - menu_command() ]- WARNING - Нет такого меню MENU_8
08/08/2020 16:41:14 - [     main.py: 82 -     <module>() ]- INFO - Телеграм бот запущен
08/08/2020 16:41:32 - [     main.py: 67 - menu_command() ]- WARNING - Нет такого меню MENU_8
08/08/2020 16:41:40 - [     main.py: 67 - menu_command() ]- WARNING - Нет такого меню MENU_9
08/08/2020 16:41:42 - [     main.py: 67 - menu_command() ]- WARNING - Нет такого меню MENU_10
08/08/2020 16:44:11 - [     main.py: 83 -     <module>() ]- INFO - Телеграм бот запущен
08/08/2020 16:44:24 - [     main.py: 83 -     <module>() ]- INFO - Телеграм бот запущен
08/08/2020 16:44:56 - [     main.py: 83 -     <module>() ]- INFO - Телеграм бот запущен
08/08/2020 16:49:48 - [     main.py: 78 -     <module>() ]- INFO - Телеграм бот запущен
08/08/2020 16:50:06 - [     main.py: 70 - menu_command() ]- WARNING - Нет такого меню MENU_8
08/08/2020 16:50:08 - [     main.py: 60 - menu_command() ]- INFO - Отправляю запрос
08/08/2020 16:50:32 - [     main.py: 78 -     <module>() ]- INFO - Телеграм бот запущен
08/08/2020 16:50:43 - [     main.py: 70 - menu_command() ]- WARNING - Нет такого меню MENU_8
08/08/2020 16:50:45 - [     main.py: 60 - menu_command() ]- INFO - Отправляю запрос
08/08/2020 16:50:50 - [     main.py: 60 - menu_command() ]- INFO - Отправляю запрос
08/08/2020 16:51:09 - [     main.py: 78 -     <module>() ]- INFO - Телеграм бот запущен
08/08/2020 16:51:24 - [     main.py: 70 - menu_command() ]- WARNING - Нет такого меню MENU_8
08/08/2020 16:51:46 - [     main.py: 70 - menu_command() ]- WARNING - Нет такого меню MENU_8
08/08/2020 16:51:48 - [     main.py: 60 - menu_command() ]- INFO - Отправляю запрос
08/08/2020 16:55:06 - [     main.py: 78 -     <module>() ]- INFO - Телеграм бот запущен
08/08/2020 16:55:19 - [     main.py: 70 - menu_command() ]- WARNING - Нет такого меню MENU_8
08/08/2020 16:56:47 - [     main.py: 82 -     <module>() ]- INFO - Телеграм бот запущен
08/08/2020 16:57:00 - [     main.py: 74 - menu_command() ]- WARNING - Нет такого меню MENU_8
08/08/2020 16:57:01 - [     main.py: 60 - menu_command() ]- INFO - Отправляю запрос
08/08/2020 16:59:22 - [     main.py: 82 -     <module>() ]- INFO - Телеграм бот запущен
08/08/2020 16:59:35 - [     main.py: 74 - menu_command() ]- WARNING - Нет такого меню MENU_8
08/08/2020 16:59:39 - [     main.py: 60 - menu_command() ]- INFO - Отправляю запрос
08/08/2020 16:59:39 - [     util.py: 68 -          run() ]- ERROR - ApiException occurred, args=('A request to the Telegram API was unsuccessful. The server returned HTTP 400 Bad Request. Response body:\n[b\'{"ok":false,"error_code":400,"description":"Bad Request: message text is empty"}\']',)
Traceback (most recent call last):
  File "/home/zhenisd/Yandex.Disk/pythonProjectSelenium/venv/lib/python3.8/site-packages/telebot/util.py", line 62, in run
    task(*args, **kwargs)
  File "/home/zhenisd/Yandex.Disk/pythonProjectSelenium/main.py", line 66, in menu_command
    bot.send_message(message.chat.id, request, reply_markup=markup)
  File "/home/zhenisd/Yandex.Disk/pythonProjectSelenium/venv/lib/python3.8/site-packages/telebot/__init__.py", line 640, in send_message
    apihelper.send_message(self.token, chat_id, text, disable_web_page_preview, reply_to_message_id,
  File "/home/zhenisd/Yandex.Disk/pythonProjectSelenium/venv/lib/python3.8/site-packages/telebot/apihelper.py", line 166, in send_message
    return _make_request(token, method_url, params=payload, method='post')
  File "/home/zhenisd/Yandex.Disk/pythonProjectSelenium/venv/lib/python3.8/site-packages/telebot/apihelper.py", line 69, in _make_request
    return _check_result(method_name, result)['result']
  File "/home/zhenisd/Yandex.Disk/pythonProjectSelenium/venv/lib/python3.8/site-packages/telebot/apihelper.py", line 88, in _check_result
    raise ApiException(msg, method_name, result)
telebot.apihelper.ApiException: A request to the Telegram API was unsuccessful. The server returned HTTP 400 Bad Request. Response body:
[b'{"ok":false,"error_code":400,"description":"Bad Request: message text is empty"}']

08/08/2020 16:59:39 - [ __init__.py:455 - __threaded_polling() ]- ERROR - A request to the Telegram API was unsuccessful. The server returned HTTP 400 Bad Request. Response body:
[b'{"ok":false,"error_code":400,"description":"Bad Request: message text is empty"}']
08/08/2020 17:00:04 - [     main.py: 82 -     <module>() ]- INFO - Телеграм бот запущен
08/08/2020 17:00:15 - [     main.py: 74 - menu_command() ]- WARNING - Нет такого меню MENU_8
08/08/2020 17:00:17 - [     main.py: 60 - menu_command() ]- INFO - Отправляю запрос
08/08/2020 17:04:25 - [     main.py: 84 -     <module>() ]- INFO - Телеграм бот запущен
08/08/2020 17:05:17 - [     main.py: 84 -     <module>() ]- INFO - Телеграм бот запущен
08/08/2020 17:06:23 - [     main.py: 84 -     <module>() ]- INFO - Телеграм бот запущен
08/08/2020 17:07:03 - [     main.py: 84 -     <module>() ]- INFO - Телеграм бот запущен
08/08/2020 17:08:02 - [     main.py: 84 -     <module>() ]- INFO - Телеграм бот запущен
08/08/2020 17:09:53 - [     main.py: 84 -     <module>() ]- INFO - Телеграм бот запущен
08/08/2020 17:10:17 - [     main.py: 84 -     <module>() ]- INFO - Телеграм бот запущен
08/08/2020 17:10:22 - [     util.py: 68 -          run() ]- ERROR - TypeError occurred, args=('any() takes exactly one argument (2 given)',)
Traceback (most recent call last):
  File "/home/zhenisd/Yandex.Disk/pythonProjectSelenium/venv/lib/python3.8/site-packages/telebot/util.py", line 62, in run
    task(*args, **kwargs)
  File "/home/zhenisd/Yandex.Disk/pythonProjectSelenium/main.py", line 51, in menu_command
    user_request_url = UserURLGenerator(current_url=user_request_url, message_request=message.text)
  File "/home/zhenisd/Yandex.Disk/pythonProjectSelenium/utils/files.py", line 40, in UserURLGenerator
    if any('arenda/', 'prodazha/') in current_url:
TypeError: any() takes exactly one argument (2 given)

08/08/2020 17:34:03 - [     main.py: 84 -     <module>() ]- INFO - Телеграм бот запущен
08/08/2020 17:34:05 - [     main.py: 84 -     <module>() ]- INFO - Телеграм бот запущен
08/08/2020 17:34:28 - [     util.py: 68 -          run() ]- ERROR - TypeError occurred, args=("'dict' object is not callable",)
Traceback (most recent call last):
  File "/home/zhenisd/Yandex.Disk/pythonProjectSelenium/venv/lib/python3.8/site-packages/telebot/util.py", line 62, in run
    task(*args, **kwargs)
  File "/home/zhenisd/Yandex.Disk/pythonProjectSelenium/main.py", line 51, in menu_command
    user_request_url = UserURLGenerator(current_url=user_request_url, message_request=message.text)
  File "/home/zhenisd/Yandex.Disk/pythonProjectSelenium/utils/files.py", line 37, in UserURLGenerator
    url_dict = config('url_dict')
TypeError: 'dict' object is not callable

08/08/2020 17:34:59 - [     main.py: 84 -     <module>() ]- INFO - Телеграм бот запущен
08/08/2020 17:35:02 - [     util.py: 68 -          run() ]- ERROR - TypeError occurred, args=('list indices must be integers or slices, not str',)
Traceback (most recent call last):
  File "/home/zhenisd/Yandex.Disk/pythonProjectSelenium/venv/lib/python3.8/site-packages/telebot/util.py", line 62, in run
    task(*args, **kwargs)
  File "/home/zhenisd/Yandex.Disk/pythonProjectSelenium/main.py", line 51, in menu_command
    user_request_url = UserURLGenerator(current_url=user_request_url, message_request=message.text)
  File "/home/zhenisd/Yandex.Disk/pythonProjectSelenium/utils/files.py", line 40, in UserURLGenerator
    current_url += url_dict[message_request]
TypeError: list indices must be integers or slices, not str

08/08/2020 17:35:59 - [     main.py: 84 -     <module>() ]- INFO - Телеграм бот запущен
08/08/2020 17:36:10 - [     main.py: 84 -     <module>() ]- INFO - Телеграм бот запущен
08/08/2020 17:36:17 - [     main.py: 84 -     <module>() ]- INFO - Телеграм бот запущен
08/08/2020 17:36:30 - [     main.py: 84 -     <module>() ]- INFO - Телеграм бот запущен
08/08/2020 17:36:38 - [     main.py: 84 -     <module>() ]- INFO - Телеграм бот запущен
08/08/2020 17:36:40 - [     util.py: 68 -          run() ]- ERROR - TypeError occurred, args=('list indices must be integers or slices, not str',)
Traceback (most recent call last):
  File "/home/zhenisd/Yandex.Disk/pythonProjectSelenium/venv/lib/python3.8/site-packages/telebot/util.py", line 62, in run
    task(*args, **kwargs)
  File "/home/zhenisd/Yandex.Disk/pythonProjectSelenium/main.py", line 51, in menu_command
    user_request_url = UserURLGenerator(current_url=user_request_url, message_request=message.text)
  File "/home/zhenisd/Yandex.Disk/pythonProjectSelenium/utils/files.py", line 40, in UserURLGenerator
    current_url += url_dict[message_request]
TypeError: list indices must be integers or slices, not str

08/08/2020 17:41:38 - [     main.py: 84 -     <module>() ]- INFO - Телеграм бот запущен
08/08/2020 17:44:05 - [     main.py: 84 -     <module>() ]- INFO - Телеграм бот запущен
08/08/2020 17:45:57 - [     main.py: 84 -     <module>() ]- INFO - Телеграм бот запущен
08/08/2020 17:46:28 - [     main.py: 84 -     <module>() ]- INFO - Телеграм бот запущен
08/08/2020 17:46:32 - [     util.py: 68 -          run() ]- ERROR - UnboundLocalError occurred, args=("local variable 'result' referenced before assignment",)
Traceback (most recent call last):
  File "/home/zhenisd/Yandex.Disk/pythonProjectSelenium/venv/lib/python3.8/site-packages/telebot/util.py", line 62, in run
    task(*args, **kwargs)
  File "/home/zhenisd/Yandex.Disk/pythonProjectSelenium/main.py", line 51, in menu_command
    user_request_url = UserURLGenerator(current_url=user_request_url, message_request=message.text)
  File "/home/zhenisd/Yandex.Disk/pythonProjectSelenium/utils/files.py", line 40, in UserURLGenerator
    return result
UnboundLocalError: local variable 'result' referenced before assignment

08/08/2020 17:46:47 - [     main.py: 84 -     <module>() ]- INFO - Телеграм бот запущен
08/08/2020 17:48:07 - [     main.py: 85 -     <module>() ]- INFO - Телеграм бот запущен
08/08/2020 17:51:40 - [     main.py: 85 -     <module>() ]- INFO - Телеграм бот запущен
08/08/2020 17:52:03 - [     main.py: 85 -     <module>() ]- INFO - Телеграм бот запущен
08/08/2020 17:53:57 - [     main.py: 85 -     <module>() ]- INFO - Телеграм бот запущен
08/08/2020 17:54:20 - [     main.py: 85 -     <module>() ]- INFO - Телеграм бот запущен
08/08/2020 17:54:46 - [     main.py: 85 -     <module>() ]- INFO - Телеграм бот запущен
08/08/2020 17:55:05 - [     main.py: 85 -     <module>() ]- INFO - Телеграм бот запущен
08/08/2020 17:55:08 - [     util.py: 68 -          run() ]- ERROR - AttributeError occurred, args=("'list' object has no attribute 'keys'",)
Traceback (most recent call last):
  File "/home/zhenisd/Yandex.Disk/pythonProjectSelenium/venv/lib/python3.8/site-packages/telebot/util.py", line 62, in run
    task(*args, **kwargs)
  File "/home/zhenisd/Yandex.Disk/pythonProjectSelenium/main.py", line 52, in menu_command
    user_request_url1 = UserURLGenerator(current_url=user_request_url, message_request=message.text)
  File "/home/zhenisd/Yandex.Disk/pythonProjectSelenium/utils/files.py", line 42, in UserURLGenerator
    if message_request in url_dict.keys():
AttributeError: 'list' object has no attribute 'keys'

08/08/2020 17:56:28 - [     main.py: 85 -     <module>() ]- INFO - Телеграм бот запущен
08/08/2020 17:57:00 - [     main.py: 85 -     <module>() ]- INFO - Телеграм бот запущен
08/08/2020 17:57:35 - [     main.py: 85 -     <module>() ]- INFO - Телеграм бот запущен
08/08/2020 17:58:55 - [     main.py: 85 -     <module>() ]- INFO - Телеграм бот запущен
08/08/2020 17:59:47 - [     main.py: 85 -     <module>() ]- INFO - Телеграм бот запущен
08/08/2020 18:00:25 - [     main.py: 85 -     <module>() ]- INFO - Телеграм бот запущен
08/08/2020 18:01:12 - [     main.py: 85 -     <module>() ]- INFO - Телеграм бот запущен
08/08/2020 18:03:21 - [     main.py: 84 -     <module>() ]- INFO - Телеграм бот запущен
08/08/2020 18:03:44 - [     main.py: 84 -     <module>() ]- INFO - Телеграм бот запущен
08/08/2020 18:04:10 - [     main.py: 84 -     <module>() ]- INFO - Телеграм бот запущен
08/08/2020 18:05:26 - [     main.py: 86 -     <module>() ]- INFO - Телеграм бот запущен
08/08/2020 18:06:54 - [     main.py: 86 -     <module>() ]- INFO - Телеграм бот запущен
08/08/2020 18:07:15 - [     main.py: 78 - menu_command() ]- WARNING - Нет такого меню MENU_8
08/08/2020 18:07:17 - [     main.py: 65 - menu_command() ]- INFO - Отправляю запрос
08/08/2020 18:10:13 - [     main.py: 86 -     <module>() ]- INFO - Телеграм бот запущен
08/08/2020 18:15:53 - [     util.py: 68 -          run() ]- ERROR - ParserError occurred, args=('while parsing a block mapping', <yaml.error.Mark object at 0x7fa4ba6c9730>, "expected <block end>, but found ':'", <yaml.error.Mark object at 0x7fa4ba6c9a90>)
Traceback (most recent call last):
  File "/home/zhenisd/Yandex.Disk/pythonProjectSelenium/venv/lib/python3.8/site-packages/telebot/util.py", line 62, in run
    task(*args, **kwargs)
  File "/home/zhenisd/Yandex.Disk/pythonProjectSelenium/main.py", line 51, in menu_command
    user_request_url = UserURLGenerator(current_url=user_request_url, message_request=message.text)
  File "/home/zhenisd/Yandex.Disk/pythonProjectSelenium/utils/files.py", line 36, in UserURLGenerator
    config = load_config_yaml()
  File "/home/zhenisd/Yandex.Disk/pythonProjectSelenium/utils/files.py", line 16, in load_config_yaml
    result_config = yaml.load(stream, Loader=yaml.SafeLoader)
  File "/home/zhenisd/Yandex.Disk/pythonProjectSelenium/venv/lib/python3.8/site-packages/yaml/__init__.py", line 114, in load
    return loader.get_single_data()
  File "/home/zhenisd/Yandex.Disk/pythonProjectSelenium/venv/lib/python3.8/site-packages/yaml/constructor.py", line 49, in get_single_data
    node = self.get_single_node()
  File "/home/zhenisd/Yandex.Disk/pythonProjectSelenium/venv/lib/python3.8/site-packages/yaml/composer.py", line 36, in get_single_node
    document = self.compose_document()
  File "/home/zhenisd/Yandex.Disk/pythonProjectSelenium/venv/lib/python3.8/site-packages/yaml/composer.py", line 55, in compose_document
    node = self.compose_node(None, None)
  File "/home/zhenisd/Yandex.Disk/pythonProjectSelenium/venv/lib/python3.8/site-packages/yaml/composer.py", line 84, in compose_node
    node = self.compose_mapping_node(anchor)
  File "/home/zhenisd/Yandex.Disk/pythonProjectSelenium/venv/lib/python3.8/site-packages/yaml/composer.py", line 133, in compose_mapping_node
    item_value = self.compose_node(node, item_key)
  File "/home/zhenisd/Yandex.Disk/pythonProjectSelenium/venv/lib/python3.8/site-packages/yaml/composer.py", line 84, in compose_node
    node = self.compose_mapping_node(anchor)
  File "/home/zhenisd/Yandex.Disk/pythonProjectSelenium/venv/lib/python3.8/site-packages/yaml/composer.py", line 127, in compose_mapping_node
    while not self.check_event(MappingEndEvent):
  File "/home/zhenisd/Yandex.Disk/pythonProjectSelenium/venv/lib/python3.8/site-packages/yaml/parser.py", line 98, in check_event
    self.current_event = self.state()
  File "/home/zhenisd/Yandex.Disk/pythonProjectSelenium/venv/lib/python3.8/site-packages/yaml/parser.py", line 425, in parse_block_mapping_first_key
    return self.parse_block_mapping_key()
  File "/home/zhenisd/Yandex.Disk/pythonProjectSelenium/venv/lib/python3.8/site-packages/yaml/parser.py", line 438, in parse_block_mapping_key
    raise ParserError("while parsing a block mapping", self.marks[-1],
yaml.parser.ParserError: while parsing a block mapping
expected <block end>, but found ':'
  in "config.yaml", line 111, column 4

08/08/2020 18:18:31 - [     main.py: 86 -     <module>() ]- INFO - Телеграм бот запущен
08/08/2020 18:19:08 - [     main.py: 78 - menu_command() ]- WARNING - Нет такого меню MENU_8
08/08/2020 18:20:19 - [     main.py: 86 -     <module>() ]- INFO - Телеграм бот запущен
08/08/2020 18:20:26 - [     main.py: 86 -     <module>() ]- INFO - Телеграм бот запущен
08/08/2020 18:26:25 - [     main.py: 86 -     <module>() ]- INFO - Телеграм бот запущен
08/08/2020 18:31:14 - [     main.py: 86 -     <module>() ]- INFO - Телеграм бот запущен
08/08/2020 18:31:38 - [     main.py: 78 - menu_command() ]- WARNING - Нет такого меню MENU_8
08/08/2020 18:48:35 - [     main.py: 86 -     <module>() ]- INFO - Телеграм бот запущен
08/08/2020 18:48:49 - [     main.py: 78 - menu_command() ]- WARNING - Нет такого меню MENU_5
08/08/2020 18:48:51 - [     main.py: 65 - menu_command() ]- INFO - Отправляю запрос
08/08/2020 18:49:21 - [     main.py: 86 -     <module>() ]- INFO - Телеграм бот запущен
08/08/2020 18:49:34 - [     main.py: 78 - menu_command() ]- WARNING - Нет такого меню MENU_5
08/08/2020 18:49:36 - [     main.py: 65 - menu_command() ]- INFO - Отправляю запрос
08/08/2020 18:50:38 - [     main.py: 86 -     <module>() ]- INFO - Телеграм бот запущен
08/08/2020 18:50:47 - [     main.py: 78 - menu_command() ]- WARNING - Нет такого меню MENU_5
08/08/2020 18:50:55 - [     main.py: 78 - menu_command() ]- WARNING - Нет такого меню MENU_5
08/08/2020 18:50:57 - [     main.py: 65 - menu_command() ]- INFO - Отправляю запрос
08/08/2020 18:50:58 - [     util.py: 68 -          run() ]- ERROR - AttributeError occurred, args=("'dict' object has no attribute 'text_h'",)
Traceback (most recent call last):
  File "/home/zhenisd/Yandex.Disk/pythonProjectSelenium/venv/lib/python3.8/site-packages/telebot/util.py", line 62, in run
    task(*args, **kwargs)
  File "/home/zhenisd/Yandex.Disk/pythonProjectSelenium/main.py", line 70, in menu_command
    bot.send_message(message.chat.id, request.text_h, reply_markup=markup)
AttributeError: 'dict' object has no attribute 'text_h'

08/08/2020 18:53:25 - [     main.py: 87 -     <module>() ]- INFO - Телеграм бот запущен
08/08/2020 18:53:36 - [     main.py: 79 - menu_command() ]- WARNING - Нет такого меню MENU_5
08/08/2020 18:53:37 - [     main.py: 65 - menu_command() ]- INFO - Отправляю запрос
08/08/2020 19:09:30 - [     main.py: 87 -     <module>() ]- INFO - Телеграм бот запущен
08/08/2020 19:09:41 - [     main.py: 79 - menu_command() ]- WARNING - Нет такого меню MENU_5
08/08/2020 19:09:43 - [     main.py: 65 - menu_command() ]- INFO - Отправляю запрос
08/08/2020 19:09:44 - [     util.py: 68 -          run() ]- ERROR - TypeError occurred, args=("unsupported operand type(s) for +: 'int' and 'str'",)
Traceback (most recent call last):
  File "/home/zhenisd/Yandex.Disk/pythonProjectSelenium/venv/lib/python3.8/site-packages/telebot/util.py", line 62, in run
    task(*args, **kwargs)
  File "/home/zhenisd/Yandex.Disk/pythonProjectSelenium/main.py", line 71, in menu_command
    bot.send_message(message.chat.id, i + krisha_ads.adverts[i].advert_id, reply_markup=markup)
TypeError: unsupported operand type(s) for +: 'int' and 'str'

08/08/2020 19:10:14 - [     main.py: 88 -     <module>() ]- INFO - Телеграм бот запущен
08/08/2020 19:10:24 - [     main.py: 80 - menu_command() ]- WARNING - Нет такого меню MENU_5
08/08/2020 19:10:26 - [     main.py: 65 - menu_command() ]- INFO - Отправляю запрос
08/08/2020 19:10:28 - [     util.py: 68 -          run() ]- ERROR - AttributeError occurred, args=("'int' object has no attribute 'advert_id'",)
Traceback (most recent call last):
  File "/home/zhenisd/Yandex.Disk/pythonProjectSelenium/venv/lib/python3.8/site-packages/telebot/util.py", line 62, in run
    task(*args, **kwargs)
  File "/home/zhenisd/Yandex.Disk/pythonProjectSelenium/main.py", line 71, in menu_command
    print(i.advert_id)
AttributeError: 'int' object has no attribute 'advert_id'

08/08/2020 19:11:23 - [     main.py: 90 -     <module>() ]- INFO - Телеграм бот запущен
08/08/2020 19:11:33 - [     main.py: 82 - menu_command() ]- WARNING - Нет такого меню MENU_5
08/08/2020 19:11:34 - [     main.py: 65 - menu_command() ]- INFO - Отправляю запрос
08/08/2020 19:11:54 - [     main.py: 90 -     <module>() ]- INFO - Телеграм бот запущен
08/08/2020 19:11:56 - [     main.py: 65 - menu_command() ]- INFO - Отправляю запрос
08/08/2020 19:12:05 - [     main.py: 82 - menu_command() ]- WARNING - Нет такого меню MENU_5
08/08/2020 19:12:12 - [     main.py: 82 - menu_command() ]- WARNING - Нет такого меню MENU_5
08/08/2020 19:12:14 - [     main.py: 65 - menu_command() ]- INFO - Отправляю запрос
08/08/2020 19:13:07 - [     main.py: 90 -     <module>() ]- INFO - Телеграм бот запущен
08/08/2020 19:13:17 - [     main.py: 82 - menu_command() ]- WARNING - Нет такого меню MENU_5
08/08/2020 19:13:18 - [     main.py: 65 - menu_command() ]- INFO - Отправляю запрос
08/08/2020 19:14:49 - [     main.py: 82 - menu_command() ]- WARNING - Нет такого меню MENU_5
08/08/2020 19:14:50 - [     main.py: 65 - menu_command() ]- INFO - Отправляю запрос
08/08/2020 19:16:09 - [     main.py: 90 -     <module>() ]- INFO - Телеграм бот запущен
08/08/2020 19:16:21 - [     main.py: 82 - menu_command() ]- WARNING - Нет такого меню MENU_5
08/08/2020 19:16:27 - [     main.py: 65 - menu_command() ]- INFO - Отправляю запрос
08/08/2020 19:16:56 - [     main.py: 82 - menu_command() ]- WARNING - Нет такого меню MENU_5
08/08/2020 19:16:57 - [     main.py: 65 - menu_command() ]- INFO - Отправляю запрос
08/08/2020 19:18:29 - [     main.py: 90 -     <module>() ]- INFO - Телеграм бот запущен
08/08/2020 19:18:42 - [     main.py: 82 - menu_command() ]- WARNING - Нет такого меню MENU_5
08/08/2020 19:18:43 - [     main.py: 65 - menu_command() ]- INFO - Отправляю запрос
08/08/2020 19:19:22 - [     main.py: 90 -     <module>() ]- INFO - Телеграм бот запущен
08/08/2020 19:19:52 - [     main.py: 90 -     <module>() ]- INFO - Телеграм бот запущен
08/08/2020 19:20:03 - [     main.py: 82 - menu_command() ]- WARNING - Нет такого меню MENU_5
08/08/2020 19:20:07 - [     main.py: 65 - menu_command() ]- INFO - Отправляю запрос
08/08/2020 19:32:50 - [     main.py: 91 -     <module>() ]- INFO - Телеграм бот запущен
08/08/2020 19:33:18 - [     main.py: 83 - menu_command() ]- WARNING - Нет такого меню MENU_8
08/08/2020 19:33:22 - [     main.py: 65 - menu_command() ]- INFO - Отправляю запрос
08/08/2020 19:34:32 - [     main.py: 86 -     <module>() ]- INFO - Телеграм бот запущен
08/08/2020 19:35:14 - [     main.py: 86 -     <module>() ]- INFO - Телеграм бот запущен
08/08/2020 19:35:38 - [     main.py: 88 -     <module>() ]- INFO - Телеграм бот запущен
08/08/2020 19:35:48 - [     main.py: 89 -     <module>() ]- INFO - Телеграм бот запущен
08/08/2020 19:36:00 - [     main.py: 90 -     <module>() ]- INFO - Телеграм бот запущен
08/08/2020 19:36:10 - [     main.py: 91 -     <module>() ]- INFO - Телеграм бот запущен
08/08/2020 19:36:34 - [     main.py: 93 -     <module>() ]- INFO - Телеграм бот запущен
08/08/2020 19:36:52 - [     main.py: 95 -     <module>() ]- INFO - Телеграм бот запущен
08/08/2020 19:37:09 - [     main.py: 96 -     <module>() ]- INFO - Телеграм бот запущен
08/08/2020 19:37:26 - [     main.py: 97 -     <module>() ]- INFO - Телеграм бот запущен
08/08/2020 19:37:52 - [     main.py: 97 -     <module>() ]- INFO - Телеграм бот запущен
08/08/2020 19:38:03 - [     main.py: 97 -     <module>() ]- INFO - Телеграм бот запущен
08/08/2020 19:38:19 - [     main.py: 98 -     <module>() ]- INFO - Телеграм бот запущен
08/08/2020 19:39:14 - [     main.py: 86 -     <module>() ]- INFO - Телеграм бот запущен
08/08/2020 19:39:27 - [     main.py: 86 -     <module>() ]- INFO - Телеграм бот запущен
08/08/2020 19:39:42 - [     main.py: 86 -     <module>() ]- INFO - Телеграм бот запущен
08/08/2020 19:40:30 - [     main.py: 86 -     <module>() ]- INFO - Телеграм бот запущен
08/08/2020 19:40:32 - [    files.py: 57 - UserParamGenerator() ]- WARNING - Error - can only concatenate str (not "dict") to str
08/08/2020 19:40:37 - [    files.py: 57 - UserParamGenerator() ]- WARNING - Error - can only concatenate str (not "dict") to str
08/08/2020 19:40:41 - [    files.py: 57 - UserParamGenerator() ]- WARNING - Error - can only concatenate str (not "dict") to str
08/08/2020 19:40:43 - [    files.py: 57 - UserParamGenerator() ]- WARNING - Error - can only concatenate str (not "dict") to str
08/08/2020 19:40:45 - [    files.py: 57 - UserParamGenerator() ]- WARNING - Error - can only concatenate str (not "dict") to str
08/08/2020 19:40:46 - [    files.py: 57 - UserParamGenerator() ]- WARNING - Error - can only concatenate str (not "dict") to str
08/08/2020 19:40:48 - [    files.py: 57 - UserParamGenerator() ]- WARNING - Error - can only concatenate str (not "dict") to str
08/08/2020 19:40:50 - [    files.py: 57 - UserParamGenerator() ]- WARNING - Error - can only concatenate str (not "dict") to str
08/08/2020 19:40:51 - [    files.py: 57 - UserParamGenerator() ]- WARNING - Error - can only concatenate str (not "dict") to str
08/08/2020 19:40:51 - [     main.py: 78 - menu_command() ]- WARNING - Нет такого меню MENU_8
08/08/2020 19:40:52 - [    files.py: 57 - UserParamGenerator() ]- WARNING - Error - can only concatenate str (not "dict") to str
08/08/2020 19:41:21 - [     main.py: 86 -     <module>() ]- INFO - Телеграм бот запущен
08/08/2020 19:41:22 - [     util.py: 68 -          run() ]- ERROR - TypeError occurred, args=('can only concatenate str (not "dict") to str',)
Traceback (most recent call last):
  File "/home/zhenisd/Yandex.Disk/pythonProjectSelenium/venv/lib/python3.8/site-packages/telebot/util.py", line 62, in run
    task(*args, **kwargs)
  File "/home/zhenisd/Yandex.Disk/pythonProjectSelenium/main.py", line 52, in menu_command
    user_request_params = UserParamGenerator(current_dict={}, message_request=message.text)
  File "/home/zhenisd/Yandex.Disk/pythonProjectSelenium/utils/files.py", line 51, in UserParamGenerator
    result = '&' + current_dict + params_dict[message_request]
TypeError: can only concatenate str (not "dict") to str

08/08/2020 19:41:32 - [     main.py: 86 -     <module>() ]- INFO - Телеграм бот запущен
08/08/2020 22:17:21 - [     main.py: 78 - menu_command() ]- WARNING - Нет такого меню MENU_8
08/08/2020 22:17:24 - [     main.py: 63 - menu_command() ]- INFO - Отправляю запрос
08/08/2020 22:17:24 - [     util.py: 68 -          run() ]- ERROR - UnboundLocalError occurred, args=("local variable 'i' referenced before assignment",)
Traceback (most recent call last):
  File "/home/zhenisd/Yandex.Disk/pythonProjectSelenium/venv/lib/python3.8/site-packages/telebot/util.py", line 62, in run
    task(*args, **kwargs)
  File "/home/zhenisd/Yandex.Disk/pythonProjectSelenium/main.py", line 70, in menu_command
    bot.send_message(message.chat.id, i, reply_markup=markup)
UnboundLocalError: local variable 'i' referenced before assignment

08/08/2020 23:42:50 - [     main.py: 87 -     <module>() ]- INFO - Телеграм бот запущен
08/08/2020 23:43:14 - [     main.py: 79 - menu_command() ]- WARNING - Нет такого меню MENU_8
08/08/2020 23:43:35 - [     main.py: 63 - menu_command() ]- INFO - Отправляю запрос
08/08/2020 23:43:35 - [resources.py: 58 -     __init__() ]- INFO - URL https://krisha.kz/arenda/kvartiry/nur-sultan/ [200]
08/08/2020 23:43:36 - [     util.py: 68 -          run() ]- ERROR - AttributeError occurred, args=("'int' object has no attribute 'advert_id'",)
Traceback (most recent call last):
  File "/home/zhenisd/Yandex.Disk/pythonProjectSelenium/venv/lib/python3.8/site-packages/telebot/util.py", line 62, in run
    task(*args, **kwargs)
  File "/home/zhenisd/Yandex.Disk/pythonProjectSelenium/main.py", line 70, in menu_command
    print(i.advert_id[i])
AttributeError: 'int' object has no attribute 'advert_id'

08/08/2020 23:43:52 - [     main.py: 88 -     <module>() ]- INFO - Телеграм бот запущен
08/08/2020 23:44:15 - [     main.py: 80 - menu_command() ]- WARNING - Нет такого меню MENU_8
08/08/2020 23:44:17 - [     main.py: 63 - menu_command() ]- INFO - Отправляю запрос
08/08/2020 23:44:17 - [resources.py: 58 -     __init__() ]- INFO - URL https://krisha.kz/arenda/kvartiry/nur-sultan/ [200]
08/08/2020 23:44:28 - [     main.py: 63 - menu_command() ]- INFO - Отправляю запрос
08/08/2020 23:44:29 - [resources.py: 58 -     __init__() ]- INFO - URL https://krisha.kz/arenda/kvartiry/nur-sultan/ [200]
08/08/2020 23:44:54 - [     main.py: 87 -     <module>() ]- INFO - Телеграм бот запущен
08/08/2020 23:45:18 - [     main.py: 79 - menu_command() ]- WARNING - Нет такого меню MENU_8
08/08/2020 23:45:20 - [     main.py: 63 - menu_command() ]- INFO - Отправляю запрос
08/08/2020 23:45:21 - [resources.py: 58 -     __init__() ]- INFO - URL https://krisha.kz/arenda/kvartiry/nur-sultan/ [200]
08/08/2020 23:45:21 - [     util.py: 68 -          run() ]- ERROR - AttributeError occurred, args=("'int' object has no attribute 'advert_id'",)
Traceback (most recent call last):
  File "/home/zhenisd/Yandex.Disk/pythonProjectSelenium/venv/lib/python3.8/site-packages/telebot/util.py", line 62, in run
    task(*args, **kwargs)
  File "/home/zhenisd/Yandex.Disk/pythonProjectSelenium/main.py", line 69, in menu_command
    print(i.advert_id[i])
AttributeError: 'int' object has no attribute 'advert_id'

08/08/2020 23:45:38 - [     main.py: 87 -     <module>() ]- INFO - Телеграм бот запущен
08/08/2020 23:46:01 - [     main.py: 79 - menu_command() ]- WARNING - Нет такого меню MENU_8
08/08/2020 23:46:06 - [     main.py: 63 - menu_command() ]- INFO - Отправляю запрос
08/08/2020 23:46:07 - [resources.py: 58 -     __init__() ]- INFO - URL https://krisha.kz/arenda/kvartiry/nur-sultan/ [200]
08/08/2020 23:51:01 - [     main.py: 87 -     <module>() ]- INFO - Телеграм бот запущен
08/08/2020 23:51:12 - [     main.py: 79 - menu_command() ]- WARNING - Нет такого меню MENU_8
08/08/2020 23:51:14 - [     main.py: 63 - menu_command() ]- INFO - Отправляю запрос
08/08/2020 23:51:14 - [resources.py: 58 -     __init__() ]- INFO - URL https://krisha.kz/arenda/doma/nur-sultan/ [200]
08/08/2020 23:51:15 - [     util.py: 68 -          run() ]- ERROR - TypeError occurred, args=("'KrishaWeb' object is not iterable",)
Traceback (most recent call last):
  File "/home/zhenisd/Yandex.Disk/pythonProjectSelenium/venv/lib/python3.8/site-packages/telebot/util.py", line 62, in run
    task(*args, **kwargs)
  File "/home/zhenisd/Yandex.Disk/pythonProjectSelenium/main.py", line 68, in menu_command
    for i in krisha_ads:
TypeError: 'KrishaWeb' object is not iterable

08/08/2020 23:53:14 - [     main.py: 87 -     <module>() ]- INFO - Телеграм бот запущен
08/08/2020 23:53:31 - [     main.py: 79 - menu_command() ]- WARNING - Нет такого меню MENU_8
08/08/2020 23:59:51 - [     main.py: 87 -     <module>() ]- INFO - Телеграм бот запущен
